<mujoco>
	<option gravity = "0 0 -9.81" />
	<worldbody>
        <light diffuse="1 1 1" pos="0 0 10" dir="0 0 -1"/>
		<geom type="plane" size="5 5 0.1" rgba="0.7 0.7 0.7 1"/>

		<body pos="0.5 0 1" euler="0 90 0">
			<joint type="hinge" axis="-1 0 0" pos="0 0 -0.5"/>
			<geom type="cylinder" size=".05 .5" rgba="1 0.0 0.0 1"/>
            <body pos="0 0 1" euler="0 0 0">
                <joint type="hinge" axis="-1 0 0" pos="0 0 -0.5"/>
                <geom type="cylinder" size="0.05 0.5" rgba="0.0 1 0.0 1"/>
                <site name="tip" size="0.1" pos="0 0 0.5" />
            </body>
		</body>
		
		<!-- <body pos="0 0 1.5" euler = "0 90 0">
			<joint type="free"/>
			<geom type="box" size=".1 .2 .3" rgba="0 0 .9 1"/>
		</body>

		<body pos="0.2 0 1.8" euler = "0 90 0">
			<joint type="free"/>
			<geom type="sphere" size=".1" rgba=".9 0 0  1"/>
		</body> -->
	</worldbody>
    <sensor>
        <framepos objtype="site" objname="tip"/>
    </sensor>
</mujoco>
